2022-07-05 14:15:23,963: ERROR	pgadmin:	Exception when checking for update
Traceback (most recent call last):
  File "/usr/lib/python3.8/urllib/request.py", line 1354, in do_open
    h.request(req.get_method(), req.selector, req.data, headers,
  File "/usr/lib/python3.8/http/client.py", line 1256, in request
    self._send_request(method, url, body, headers, encode_chunked)
  File "/usr/lib/python3.8/http/client.py", line 1302, in _send_request
    self.endheaders(body, encode_chunked=encode_chunked)
  File "/usr/lib/python3.8/http/client.py", line 1251, in endheaders
    self._send_output(message_body, encode_chunked=encode_chunked)
  File "/usr/lib/python3.8/http/client.py", line 1011, in _send_output
    self.send(msg)
  File "/usr/lib/python3.8/http/client.py", line 951, in send
    self.connect()
  File "/usr/lib/python3.8/http/client.py", line 1418, in connect
    super().connect()
  File "/usr/lib/python3.8/http/client.py", line 922, in connect
    self.sock = self._create_connection(
  File "/usr/lib/python3.8/socket.py", line 808, in create_connection
    raise err
  File "/usr/lib/python3.8/socket.py", line 796, in create_connection
    sock.connect(sa)
OSError: [Errno 101] Network is unreachable

During handling of the above exception, another exception occurred:

Traceback (most recent call last):
  File "/opt/pgadmin4/venv/lib/python3.8/site-packages/pgadmin4/pgadmin/browser/__init__.py", line 630, in check_browser_upgrade
    response = urlopen(url, data, 5)
  File "/usr/lib/python3.8/urllib/request.py", line 222, in urlopen
    return opener.open(url, data, timeout)
  File "/usr/lib/python3.8/urllib/request.py", line 525, in open
    response = self._open(req, data)
  File "/usr/lib/python3.8/urllib/request.py", line 542, in _open
    result = self._call_chain(self.handle_open, protocol, protocol +
  File "/usr/lib/python3.8/urllib/request.py", line 502, in _call_chain
    result = func(*args)
  File "/usr/lib/python3.8/urllib/request.py", line 1397, in https_open
    return self.do_open(http.client.HTTPSConnection, req,
  File "/usr/lib/python3.8/urllib/request.py", line 1357, in do_open
    raise URLError(err)
urllib.error.URLError: <urlopen error [Errno 101] Network is unreachable>
2022-07-05 14:15:45,424: ERROR	pgadmin:	400 Bad Request: The CSRF session token is missing.
Traceback (most recent call last):
  File "/opt/pgadmin4/venv/lib/python3.8/site-packages/flask_wtf/csrf.py", line 261, in protect
    validate_csrf(self._get_csrf_token())
  File "/opt/pgadmin4/venv/lib/python3.8/site-packages/flask_wtf/csrf.py", line 103, in validate_csrf
    raise ValidationError("The CSRF session token is missing.")
wtforms.validators.ValidationError: The CSRF session token is missing.

During handling of the above exception, another exception occurred:

Traceback (most recent call last):
  File "/opt/pgadmin4/venv/lib/python3.8/site-packages/flask/app.py", line 1521, in full_dispatch_request
    rv = self.preprocess_request()
  File "/opt/pgadmin4/venv/lib/python3.8/site-packages/flask/app.py", line 1861, in preprocess_request
    rv = self.ensure_sync(before_func)()
  File "/opt/pgadmin4/venv/lib/python3.8/site-packages/flask_wtf/csrf.py", line 229, in csrf_protect
    self.protect()
  File "/opt/pgadmin4/venv/lib/python3.8/site-packages/flask_wtf/csrf.py", line 264, in protect
    self._error_response(e.args[0])
  File "/opt/pgadmin4/venv/lib/python3.8/site-packages/flask_wtf/csrf.py", line 307, in _error_response
    raise CSRFError(reason)
flask_wtf.csrf.CSRFError: 400 Bad Request: The CSRF session token is missing.
2022-07-05 14:15:49,716: ERROR	pgadmin:	400 Bad Request: The CSRF session token is missing.
Traceback (most recent call last):
  File "/opt/pgadmin4/venv/lib/python3.8/site-packages/flask_wtf/csrf.py", line 261, in protect
    validate_csrf(self._get_csrf_token())
  File "/opt/pgadmin4/venv/lib/python3.8/site-packages/flask_wtf/csrf.py", line 103, in validate_csrf
    raise ValidationError("The CSRF session token is missing.")
wtforms.validators.ValidationError: The CSRF session token is missing.

During handling of the above exception, another exception occurred:

Traceback (most recent call last):
  File "/opt/pgadmin4/venv/lib/python3.8/site-packages/flask/app.py", line 1521, in full_dispatch_request
    rv = self.preprocess_request()
  File "/opt/pgadmin4/venv/lib/python3.8/site-packages/flask/app.py", line 1861, in preprocess_request
    rv = self.ensure_sync(before_func)()
  File "/opt/pgadmin4/venv/lib/python3.8/site-packages/flask_wtf/csrf.py", line 229, in csrf_protect
    self.protect()
  File "/opt/pgadmin4/venv/lib/python3.8/site-packages/flask_wtf/csrf.py", line 264, in protect
    self._error_response(e.args[0])
  File "/opt/pgadmin4/venv/lib/python3.8/site-packages/flask_wtf/csrf.py", line 307, in _error_response
    raise CSRFError(reason)
flask_wtf.csrf.CSRFError: 400 Bad Request: The CSRF session token is missing.
2022-07-05 14:15:49,891: ERROR	pgadmin:	400 Bad Request: The CSRF session token is missing.
Traceback (most recent call last):
  File "/opt/pgadmin4/venv/lib/python3.8/site-packages/flask_wtf/csrf.py", line 261, in protect
    validate_csrf(self._get_csrf_token())
  File "/opt/pgadmin4/venv/lib/python3.8/site-packages/flask_wtf/csrf.py", line 103, in validate_csrf
    raise ValidationError("The CSRF session token is missing.")
wtforms.validators.ValidationError: The CSRF session token is missing.

During handling of the above exception, another exception occurred:

Traceback (most recent call last):
  File "/opt/pgadmin4/venv/lib/python3.8/site-packages/flask/app.py", line 1521, in full_dispatch_request
    rv = self.preprocess_request()
  File "/opt/pgadmin4/venv/lib/python3.8/site-packages/flask/app.py", line 1861, in preprocess_request
    rv = self.ensure_sync(before_func)()
  File "/opt/pgadmin4/venv/lib/python3.8/site-packages/flask_wtf/csrf.py", line 229, in csrf_protect
    self.protect()
  File "/opt/pgadmin4/venv/lib/python3.8/site-packages/flask_wtf/csrf.py", line 264, in protect
    self._error_response(e.args[0])
  File "/opt/pgadmin4/venv/lib/python3.8/site-packages/flask_wtf/csrf.py", line 307, in _error_response
    raise CSRFError(reason)
flask_wtf.csrf.CSRFError: 400 Bad Request: The CSRF session token is missing.
2022-07-05 14:15:55,740: ERROR	pgadmin:	400 Bad Request: The CSRF session token is missing.
Traceback (most recent call last):
  File "/opt/pgadmin4/venv/lib/python3.8/site-packages/flask_wtf/csrf.py", line 261, in protect
    validate_csrf(self._get_csrf_token())
  File "/opt/pgadmin4/venv/lib/python3.8/site-packages/flask_wtf/csrf.py", line 103, in validate_csrf
    raise ValidationError("The CSRF session token is missing.")
wtforms.validators.ValidationError: The CSRF session token is missing.

During handling of the above exception, another exception occurred:

Traceback (most recent call last):
  File "/opt/pgadmin4/venv/lib/python3.8/site-packages/flask/app.py", line 1521, in full_dispatch_request
    rv = self.preprocess_request()
  File "/opt/pgadmin4/venv/lib/python3.8/site-packages/flask/app.py", line 1861, in preprocess_request
    rv = self.ensure_sync(before_func)()
  File "/opt/pgadmin4/venv/lib/python3.8/site-packages/flask_wtf/csrf.py", line 229, in csrf_protect
    self.protect()
  File "/opt/pgadmin4/venv/lib/python3.8/site-packages/flask_wtf/csrf.py", line 264, in protect
    self._error_response(e.args[0])
  File "/opt/pgadmin4/venv/lib/python3.8/site-packages/flask_wtf/csrf.py", line 307, in _error_response
    raise CSRFError(reason)
flask_wtf.csrf.CSRFError: 400 Bad Request: The CSRF session token is missing.
2022-07-05 14:16:32,069: ERROR	pgadmin:	400 Bad Request: The CSRF session token is missing.
Traceback (most recent call last):
  File "/opt/pgadmin4/venv/lib/python3.8/site-packages/flask_wtf/csrf.py", line 261, in protect
    validate_csrf(self._get_csrf_token())
  File "/opt/pgadmin4/venv/lib/python3.8/site-packages/flask_wtf/csrf.py", line 103, in validate_csrf
    raise ValidationError("The CSRF session token is missing.")
wtforms.validators.ValidationError: The CSRF session token is missing.

During handling of the above exception, another exception occurred:

Traceback (most recent call last):
  File "/opt/pgadmin4/venv/lib/python3.8/site-packages/flask/app.py", line 1521, in full_dispatch_request
    rv = self.preprocess_request()
  File "/opt/pgadmin4/venv/lib/python3.8/site-packages/flask/app.py", line 1861, in preprocess_request
    rv = self.ensure_sync(before_func)()
  File "/opt/pgadmin4/venv/lib/python3.8/site-packages/flask_wtf/csrf.py", line 229, in csrf_protect
    self.protect()
  File "/opt/pgadmin4/venv/lib/python3.8/site-packages/flask_wtf/csrf.py", line 264, in protect
    self._error_response(e.args[0])
  File "/opt/pgadmin4/venv/lib/python3.8/site-packages/flask_wtf/csrf.py", line 307, in _error_response
    raise CSRFError(reason)
flask_wtf.csrf.CSRFError: 400 Bad Request: The CSRF session token is missing.
